2024-08-12 14:59:03,646 [fail_agent_wrapper] ERROR: 
Traceback (most recent call last):
  File "/home/benni/Documents/Studium/4. Master/Machine Learning Essentials/MLE_Bomberman/bomberman_rl/agents.py", line 248, in process_event
    event_result = getattr(module, event_name)(self.fake_self, *event_args)
                   ^^^^^^^^^^^^^^^^^^^^^^^^^^^^^^^^^^^^^^^^^^^^^^^^^^^^^^^^
  File "/home/benni/Documents/Studium/4. Master/Machine Learning Essentials/MLE_Bomberman/bomberman_rl/agent_code/fail_agent/callbacks.py", line 9, in act
    raise ValueError()
ValueError
